Workbook

Sheet 00_읽는법
B2: 성과관리 AI Agent — 신호 카탈로그
B4: 항목 | C4: 내용
B5: 문서 성격 | C5: 초기 기획 산출물. 신호를 만드는 기준(문법)에 맞춰 채운 신호 목록
B6: 작성일 | C6: 2026-07-28 · 규칙 버전 v0.1
B7: 적용 대상 | C7: 휴넬(hunel) 패키지에 내장되는 성과관리 AI Agent
B8: 원본 기획서 | C8: 성과관리Agent_신호근거행동_기획_260728.md (선행 문서: 성과관리 Agent_기획_0723.md)
B9: 읽는 사람 | C9: 검토자 = 비개발자(왼쪽 A~F열만 읽어도 무슨 알림인지 알 수 있게) / 수령자 = 개발자(G열 이후)
B10: 데이터 기준 | C10: elizax_talenx 데모 데이터 실측(2026-07-16 기준)을 휴넬 데이터 가용성의 대리 지표로 사용
B13: 이 파일이 답하는 것
B14: ① 무엇을 알려줄 만한 변화(신호)로 볼 것인가 ② 왜 알려주는지(근거)를 무엇으로 보여줄 것인가
B15: ③ 알림을 본 사람이 무엇을 하게 할 것인가(행동), 그 결과는 어디에 남는가 ④ 같은 변화를 누구에게 어떻게 다르게 보여줄 것인가
B17: 화면에 뜨는 형태는 알림 카드 한 종류다. 위에 신호 · 가운데 근거 · 아래 행동. 신호 판정은 시스템 규칙이 하고, 문장 다듬기와 초안 쓰기만 AI가 한다. AI는 초안까지만 만들고 최종 확정은 사람이 한다.
B19: 시트 안내
B20: 시트 | C20: 이름 | D20: 담는 것
B21: 1 | C21: 00_읽는법 | D21: 이 시트. 목적 · 용어 · 색·기호 · 알림 조절 기본값 · 확인 필요 목록
B22: 2 | C22: 01_신호목록 | D22: 본체. 한 줄 = 알림 1건 (22열). 주체별·단계별로 걸러 볼 수 있게 필터가 걸려 있음
B23: 3 | C23: 02_칸점검 | D23: 4단계 × 4주체 = 16칸 충족 현황 + 16칸 × 5유형 = 80 스캔포인트 결과 + 빈칸 사유
B24: 4 | C24: 03_문장·기록규칙 | D24: 문장 쓰는 규칙(좋은 예·나쁜 예) + 알림 기록으로 남길 항목
B27: 용어 풀이
B28: 용어 | C28: 뜻
B29: 신호 | C29: ① 무언가 달라졌고 ② 그 때문에 특정한 사람이 무언가를 해야 하고 ③ 그 판단을 시스템 규칙으로 할 수 있는 경우. 셋 중 하나라도 빠지면 알림으로 만들지 않는다
B30: 신호 근거 (F열) | C30: 이 알림이 왜 지금 떴는지. 규칙에 걸린 사실만 쓴다(숫자·날짜·건수 + 비교 기준). AI를 쓰지 않는다
B31: 행동 근거 (J열) | C31: 초안을 쓰기 위해 모으는 재료. 시스템이 모으고 AI가 문장으로 만든다
B32: 기초 / 우리만 가능 | C32: 기초 = 어느 시스템이나 하는 알림(주로 마감·기간). 우리만 가능 = 조직·직무·발령 정보가 있어야 나오는 알림
B33: 재알림 간격 (S열) | C33: 같은 사람에게 같은 알림을 며칠 안에 다시 띄우지 않는지
B34: 최소 건수 (T열) | C34: 합쳐서 보는 알림은 몇 건·몇 % 미만이면 띄우지 않는지
B35: 위로 올릴 3조건 | C35: ① 합쳐서 볼 수 있는가 ② 아래 사람이 먼저 처리할 기회를 가졌는가 ③ 상위 주체가 실제로 할 수 있는 일이 있는가 — 셋 다 맞을 때만 상위 주체 알림을 만든다
B38: 변화의 종류 5가지 (D열)
B39: 구분 | C39: 어떤 변화인가 | D39: 판단에 필요한 정보 | E39: 우리만 할 수 있는 정도
B40: ① 때가 됐다 | C40: 기간이 열렸거나 마감이 다가옴·지났음 | D40: 평가·목표 기간 일정 | E40: 낮음 — 기초 알림의 주력
B41: ② 비어 있다 / 멈췄다 | C41: 써야 할 게 안 써졌음 / 며칠째 그대로임 | D41: 마지막으로 고친 날짜 | E41: 중간
B42: ③ 기준을 벗어났다 | C42: 수치가 기준선 밖으로 나감 | D42: 수치 + 비교 기준 | E42: 중간~높음
B43: ④ 서로 안 맞는다 | C43: 목표가 팀 목표·직무와 어긋남, 평가와 근거가 안 맞음 | D43: 목표·조직·직무의 연결 관계 | E43: 높음
B44: ⑤ 무슨 일이 생겼다 | C44: 발령, 조직 개편, 피드백 도착, 같이 걸린 동료의 진행 | D44: 변경 이력 | E44: 매우 높음 — 휴넬만 가능
B47: 주체 4종 (C열)
B48: 주체 | C48: 무엇을 기준으로 보는가 | D48: 이 사람에게 알림이 되는 조건 | E48: 하게 될 행동
B49: 조직원 | C49: 나 자신 | D49: 변화의 대상이 나 자신일 때. 남의 변화는 나와의 연결 근거를 댈 수 있을 때만 | E49: 직접 쓰고 고치기
B50: 조직장(1차) | C50: 팀원 한 사람씩 | D50: 변화의 대상이 직속 팀원일 때 | E50: 챙기고 독려하고 1차 판단하기
B51: 조직장(2차) | C51: 팀 단위 / 1차 평가자 | D51: 개별 팀원 건은 올리지 않는다. 팀 단위로 합친 수치 또는 1차 평가자가 한 일만 | E51: 조정 요청·재검토 요구·승인
B52: HR·경영진 | C52: 조직 전체 | D52: 조직·전사 단위로 합친 수치, 진행률, 제도에서 벗어난 곳. 개인은 되도록 특정하지 않는다 | E52: HR = 제도 운영 / 경영진 = 조직·자원 판단
...

Sheet 01_신호목록
A1: [묶음 1] 어떤 알림인가 — 누구나 읽는 부분 | G1: [묶음 2] 무엇을 보고 판단하나 — 개발자가 만드는 부분 | J1: [묶음 3] 무엇을 하게 하나 | N1: [묶음 4] 채택 여부와 알림 조절
A2: 알림 번호 | B2: 성과관리 단계 | C2: 주체 | D2: 변화의 종류 | E2: 화면에 뜨는 문장 | F2: 왜 지금 떴는지 | G2: 판단 조건 | H2: 비교 기준 | I2: 필요한 정보 | J2: 초안 재료 | K2: 행동 | L2: 사용자에게 물어보는 문장 | M2: 결과가 저장되는 곳 | N2: 도움 | O2: 빈도 | P2: 우리만 | Q2: 합계 | R2: 판정 | S2: 재알림 간격 | T2: 최소 건수 | U2: 언제 사라지나 | V2: 비고 · 확인 필요
A3: 목표수립-조직원-01 | B3: 목표수립 | C3: 조직원 | D3: ① 때가 됐다 | E3: 목표 제출 마감이 3일 남았어요 | F3: 목표 제출 기한 2026-08-15까지 3일 남음; 내 이름으로 저장된 목표 0건 (FY2026-2Q 기준) | G3: 목표 작성 마감일까지 3일 이하로 남았고, 내 이름으로 저장된 목표가 1건도 없을 때 | H3: 제도 기준값 | I3: 목표 기간 일정의 마감일; 내 이름으로 저장된 목표 건수; 오늘 날짜 | J3: 내 직무프로파일의 과업 영역과 과업 목록; 소속 조직의 상위 목표; 내 지난 기간 목표 문장 | K3: A1 쓰기 | L3: 목표 초안 3개를 만들어 볼까요? | M3: 목표 기록 신규 생성 (핵심결과 포함) | N3: 3 | O3: 3 | P3: 1 | Q3: =N3+O3+P3 | R3: 기초 | S3: 3일 | T3: 해당 없음 | U3: 목표를 1건이라도 저장하면 즉시 | V3: 평가·목표 기간 일정 마스터(개시일·마감일·리마인드 기준일)가 없어 현재는 목표의 기간 문자열(FY2026-2Q)에서 파생해야 함 — 일정 마스터 신설 확인 필요(T1 신호 전체의 전제)
A4: 목표수립-조직원-02 | B4: 목표수립 | C4: 조직원 | D4: ② 비어 있다 / 멈췄다 | E4: 목표만 있고 핵심결과가 비어 있어요 | F4: 목표 G-0142 저장 후 7일 경과; 연결된 핵심결과 0건 (같은 팀 목표 평균 3.7건) | G4: 목표를 저장한 지 7일이 지났는데 그 목표에 달린 핵심결과가 1건도 없을 때 | H4: 팀 평균 | I4: 목표별 핵심결과 건수; 목표 저장일; 목표 기간의 남은 일수; 같은 팀 목표의 핵심결과 건수 | J4: 내 목표 문장; 내 직무프로파일의 과업 영역과 과업 목록; 같은 직무 동료의 핵심결과 표현 | K4: A1 쓰기 | L4: 핵심결과 3개 초안을 채워 볼까요? | M4: 핵심결과 기록 신규 생성 (목표에 연결) | N4: 3 | O4: 2 | P4: 2 | Q4: =N4+O4+P4 | R4: 우리만 가능 | S4: 7일 | T4: 해당 없음 | U4: 핵심결과를 1건 저장하면 즉시 | V4: 목표의 저장일·최종 수정 일시(updated_at)가 어디에도 없어 '7일 경과' 판정 불가 — 확인 1순위. 핵심결과 146건·목표 40건은 실측 확인
A5: 목표수립-조직원-03 | B5: 목표수립 | C5: 조직원 | D5: ③ 기준을 벗어났다 | E5: 핵심결과 가중치 합이 100%가 아니에요 | F5: 목표 G-0142의 핵심결과 4건 가중치 합 85% (제도 기준 100%) | G5: 한 목표에 달린 핵심결과들의 가중치를 더한 값이 100%에서 5%포인트 이상 벗어났을 때 | H5: 제도 기준값 | I5: 핵심결과별 가중치; 목표별 핵심결과 목록; 가중치 합계 제도 기준값 | J5: 핵심결과별 가중치와 난이도(A~C); 핵심결과별 목표값; 내가 지난 기간에 쓴 가중치 배분 | K5: A2 고치기·맞추기 | L5: 가중치를 100%로 맞춰 볼까요? | M5: 핵심결과 가중치 수정 + 수정 이력 | N5: 2 | O5: 2 | P5: 2 | Q5: =N5+O5+P5 | R5: 우리만 가능 | S5: 7일 | T5: 해당 없음 | U5: 가중치 합이 100%가 되면 즉시 | V5: 가중치 합 100% 규정이 제도로 정해져 있는지 확인 필요. 핵심결과 가중치 필드는 146건 실측 확인. 수정 이력 보관 위치는 없어 신설 확인 필요
A6: 목표수립-조직원-04 | B6: 목표수립 | C6: 조직원 | D6: ④ 서로 안 맞는다 | E6: 핵심결과가 내 직무 과업과 어긋나요 | F6: 핵심결과 3건 중 2건이 직무프로파일의 과업 영역에 연결 없음; 내 직무에서 가중치 1위 역량 D2에 걸린 핵심결과 0건 (직무프로파일 기준) | G6: 내 핵심결과 중 직무 과업에 연결되지 않은 것이 50%를 넘거나, 직무에서 가중치가 가장 높은 역량에 걸린 핵심결과가 1건도 없을 때 | H6: 제도 기준값 | I6: 핵심결과의 직무 과업 참조; 핵심결과의 역량 연결(D1~D5); 내 직무프로파일의 과업 체계와 역량별 가중치 | J6: 직무 미션과 과업 영역별 과업 목록; 가중치 높은 역량의 설명; 내 현재 핵심결과 문장; 같은 직무 동료의 핵심결과 표현 | K6: A2 고치기·맞추기 | L6: 빠진 과업 쪽으로 핵심결과를 손볼까요? | M6: 핵심결과 내용·직무 과업 연결 수정 + 수정 이력 | N6: 3 | O6: 2 | P6: 3 | Q6: =N6+O6+P6 | R6: 우리만 가능 | S6: 7일 | T6: 해당 없음 | U6: 핵심결과가 모두 과업에 연결되면 즉시 | V6: 핵심결과의 직무 과업 참조 100%·역량 연결 D1~D5·직무프로파일 98종의 역량 가중치는 실측 확인. 목표의 직무 참조는 80%여서 빠진 20%는 판정 보류. 상위 목표 미연계(목표 연결률 95%, 미연계 5%)를 같은 조건에 넣을지 확인 필요
A7: 목표수립-조직원-05 | B7: 목표수립 | C7: 조직원 | D7: ⑤ 무슨 일이 생겼다 | E7: 직무가 바뀌어 목표가 안 맞아요 | F7: 2026-07-01 발령으로 직무 변경(영업기획→사업개발); 진행 중 목표 2건이 이전 직무의 과업을 그대로 참조 중 | G7: 발령 기록에서 직무가 바뀐 날 이후 30일 안에, 이전 직무의 과업을 참조한 목표가 1건 이상 남아 있을 때 | H7: 없음 | I7: 발령·직무이동 이력의 변경일과 이전·이후 직무; 진행 중 목표·핵심결과의 직무 과업 참조; 목표 기간의 남은 일수 | J7: 새 직무프로파일의 미션·과업 목록·요구 역량; 현재 목표와 핵심결과 문장; 새 소속 조직의 상위 목표 | K7: A2 고치기·맞추기 | L7: 새 직무에 맞게 목표를 고쳐 볼까요? | M7: 목표·핵심결과 수정 + 수정 이력 (직무 변경 사유 함께 기록) | N7: 3 | O7: 1 | P7: 3 | Q7: =N7+O7+P7 | R7: 우리만 가능 | S7: 재알림 없음(1회) | T7: 해당 없음 | U7: 목표를 저장하거나 '그대로 두기'로 표시하면 즉시 | V7: 발령·직무이동 이력 채움률 0.5%(221명 중 1명) — 휴넬/JaDE 발령 원천 연동이 이 신호의 전제(T5 간판). 같은 원인으로 조직장(1차)에게도 뜰 수 있어, 조직원이 먼저 보고 7일 안에 처리하지 않을 때만 상위로 올리도록 순서 지정 필요
A8: 목표수립-조직장1차-01 | B8: 목표수립 | C8: 조직장(1차) | D8: ① 때가 됐다 | E8: 팀원 목표 마감이 사흘 남았어요 | F8: 목표수립 마감 3일 전(2026-07-31 마감), 이 팀원이 등록한 목표 0건 (제도 기준 1인 1건 이상) | G8: 목표수립 마감일까지 3일 이하로 남았고, 그 팀원이 등록한 목표가 0건일 때 | H8: 제도 기준값 | I8: 목표수립 기간의 마감일; 팀원별 등록 목표 건수; 상위자 사번으로 만든 직속 팀원 명단 | J8: 팀 목표와 핵심결과 문장; 그 팀원의 직무프로파일 과업 목록; 그 팀원이 지난 기간에 쓴 목표 문장 | K8: A3 보내기 | L8: 목표 작성을 부탁하는 메시지를 보낼까요? | M8: 메시지 기록 + 보냄·받음 기록 생성 (알림·메시지 발송·열람 원장 저장 위치 신설 필요) | N8: 3 | O8: 3 | P8: 1 | Q8: =N8+O8+P8 | R8: 기초 | S8: 3일 | T8: 해당 없음 | U8: 그 팀원이 목표를 1건 저장하면 즉시 | V8: 목표·평가 기간 일정 마스터가 없어 마감일을 목표의 기간 문자열에서 파생 중 — 일정 마스터 신설 확인 필요. 메시지 보냄·받음 원장도 서버 보존 신설 필요. 같은 원인 카드가 조직원에게 먼저 뜨므로 1차 카드는 마감 3일 전부터만 만든다
A9: 목표수립-조직장1차-02 | B9: 목표수립 | C9: 조직장(1차) | D9: ② 비어 있다 / 멈췄다 | E9: 팀원 목표에 핵심결과가 비어 있어요 | F9: 목표수립 개시 후 10일 경과, 이 팀원 목표 2건 모두 핵심결과 0건 (팀 평균 목표당 3.7건) | G9: 목표수립 기간이 시작된 뒤 7일이 지났는데, 그 팀원이 만든 목표에 핵심결과가 0건일 때 | H9: 팀 평균 | I9: 목표수립 기간의 개시일; 그 팀원 목표별 핵심결과 건수; 같은 팀 목표의 목표당 핵심결과 평균 건수 | J9: 그 팀원 목표 문장; 연결된 팀 목표의 핵심결과와 목표값; 그 팀원 직무프로파일의 과업체계와 요구스킬 | K9: A3 보내기 | L9: 핵심결과 후보를 담아 보내 드릴까요? | M9: 메시지 기록 + 해당 목표에 남는 검토 코멘트 (목표별 검토 코멘트 저장 위치 신설 필요) | N9: 3 | O9: 2 | P9: 2 | Q9: =N9+O9+P9 | R9: 우리만 가능 | S9: 7일 | T9: 해당 없음 | U9: 그 목표에 핵심결과가 1건 이상 저장되면 즉시 | V9: 핵심결과 건수는 실측 확인됨(146건). 목표 레코드에 최종 수정 일시가 없어 기간 개시일 기준으로만 판정 가능 — 일정 마스터와 수정 일시 확인 필요. 조직원에게 같은 원인 카드가 먼저 뜨며 7일 내 미처리일 때만 1차에 만든다
A10: 목표수립-조직장1차-03 | B10: 목표수립 | C10: 조직장(1차) | D10: ③ 기준을 벗어났다 | E10: 팀원 핵심결과 난이도가 낮게 몰렸어요 | F10: 이 팀원 핵심결과 6건 중 5건이 난이도 C (같은 팀 난이도 C 비중 38%) | G10: - | H10: - | I10: - | J10: - | K10: - | L10: - | M10: - | N10: 2 | O10: 1 | P10: 2 | Q10: =N10+O10+P10 | R10: 제외 | S10: - | T10: - | U10: - | V10: 난이도(A~C)와 난이도 근거는 실측 있으나, 난이도가 낮게 몰린 것이 곧 고쳐야 할 상태라고 볼 기준이 제도에 없어 제외. 난이도 근거(98.6%)를 쓰는 판정 규칙이 정해지면 다시 검토
A11: 목표수립-조직장1차-04 | B11: 목표수립 | C11: 조직장(1차) | D11: ④ 서로 안 맞는다 | E11: 팀원 목표가 팀 방향과 어긋나 있어요 | F11: 이 팀원 목표 2건 중 1건이 팀 목표에 연결 없음 (팀 목표 3건 등록, 전사 상위목표 연결률 95%) | G11: 그 팀원 목표 중 팀 목표에 연결되지 않았거나 다른 조직 목표에 연결된 것이 1건 이상일 때 | H11: 제도 기준값 | I11: 목표의 상위목표 연결; 목표 소유자의 소속조직; 우리 팀 목표 목록; 목표의 전략과제 연결 | J11: 그 팀원 목표와 핵심결과 문장; 연결 후보가 되는 우리 팀 목표 3건; 그 팀원 직무프로파일의 과업체계 | K11: A2 고치기·맞추기 | L11: 이 팀 목표로 연결을 바꿀까요? | M11: 해당 목표의 상위목표 연결 수정 + 수정 이력 기록 (목표 수정 이력 저장 위치 신설 필요) | N11: 3 | O11: 2 | P11: 3 | Q11: =N11+O11+P11 | R11: 우리만 가능 | S11: 7일 | T11: 해당 없음 | U11: 상위목표 연결이 저장되면 즉시 | V11: 상위목표 연결 95%·전략과제 연결 100% 실측 확인됨. 조직장이 팀원 목표의 연결을 직접 고칠 권한이 있는지 확인 필요 — 권한이 없으면 A3 보내기로 바꾼다. 목표 수정 이력 저장 위치 없음
A12: 목표수립-조직장1차-05 | B12: 목표수립 | C12: 조직장(1차) | D12: ⑤ 무슨 일이 생겼다 | E12: 발령 온 팀원 목표를 다시 볼 때예요 | F12: 이 팀원 소속조직 변경 7일 경과(발령일 2026-07-01), 목표 3건 모두 이전 조직 목표에 연결됨 | G12: 그 팀원의 소속조직이 바뀐 뒤 7일이 지났고, 이전 조직 목표에 연결된 목표가 1건 이상 남아 있을 때 | H12: 없음 | I12: 발령·소속조직 변경 이력과 변경일; 그 팀원 목표의 상위목표와 그 상위목표의 소속조직; 바뀐 직무프로파일 | J12: 새 직무프로파일의 과업체계와 요구스킬; 우리 팀 목표와 핵심결과; 남은 목표 기간; 이전 조직에서 쓴 목표 문장 | K12: A4 대화 잡기 | L12: 목표 재설정 대화를 잡을까요? | M12: 일정 생성 + 이야기할 항목 기록(그대로 가져올 목표·새로 만들 목표·남은 기간에 맞춘 목표값) (1on1 기록 서버 보존 신설 필요) | N12: 3 | O12: 1 | P12: 3 | Q12: =N12+O12+P12 | R12: 우리만 가능 | S12: 재알림 없음(1회) | T12: 해당 없음 | U12: 목표 재설정 대화 일정이 저장되면 즉시 | V12: 발령·직무이동 이력 채움률 0.5%(221명 중 1명) — 휴넬·JaDE 발령 원천 연동이 이 신호의 전제. 1on1 기록은 브라우저 80건 롤링뿐이어서 서버 보존 신설 필요
A13: 목표수립-조직장2차-01 | B13: 목표수립 | C13: 조직장(2차) | D13: ① 때가 됐다 | E13: 하위 3개 팀이 목표를 아직 안 세웠어요 | F13: 목표 수립 마감 3일 전, 하위 8개 팀 중 3개 팀 수립률 30% 미만 (내 조직 평균 62%) | G13: 목표 수립 마감일이 3일 이내로 남았고, 하위 팀 중 목표 수립률이 30% 미만인 팀이 1개 이상일 때 | H13: 제도 기준값 | I13: 목표 수립 기간의 마감일; 하위 팀별 구성원 수; 하위 팀별 목표 생성 건수; 내 조직 전체 수립률 | J13: 팀별 수립률 표; 마감일까지 남은 일수; 지난 분기 같은 시점의 팀별 수립률; 메시지를 받을 1차 평가자 명단 | K13: A3 보내기 | L13: 수립이 늦은 3개 팀장에게 마감 안내를 보낼까요? | M13: 메시지 기록 + 보냄·받음 기록 (알림 원장에 발송 결과 저장 — 서버 원장 신설 필요) | N13: 3 | O13: 3 | P13: 1 | Q13: =N13+O13+P13 | R13: 기초 | S13: 3일 | T13: 3건 이상 또는 팀의 30% 이상 | U13: 해당 팀 수립률이 70% 이상이 되면 즉시 | V13: 목표 기간 일정 마스터(개시일·마감일)가 없어 현재는 목표의 기간 문자열에서 파생 — 신설 필요. 억제: 같은 원인으로 각 1차 평가자에게 팀원별 미수립 알림이 먼저 뜬 뒤에만 이 팀 합계 카드를 만든다(1차 선행). 개별 팀원 미수립 건은 2차에 올리지 않는다
A14: 목표수립-조직장2차-02 | B14: 목표수립 | C14: 조직장(2차) | D14: ② 비어 있다 / 멈췄다 | E14: B팀장이 팀원 목표를 아직 안 봤어요 | F14: B팀 팀원 목표 9건 중 7건이 14일 넘게 검토 대기 (내 조직 평균 대기 3일) | G14: 한 팀의 팀원 목표 중 1차 평가자가 확정하지 않은 것이 14일 이상 남아 있고, 그 비율이 팀의 30%를 넘을 때 | H14: 팀 평균 | I14: 팀원 목표의 상태값; 목표 생성일; 1차 평가자의 목표 확정 기록과 확정 시각; 하위 팀별 평균 검토 대기 일수 | J14: 팀별 미검토 건수와 대기 일수; 해당 팀장의 지난 분기 검토 소요일; 검토가 밀린 목표 제목 묶음; 요청 문구에 넣을 사실 묶음 | K14: A6 요청하기 | L14: B팀장에게 목표 검토를 마쳐 달라고 요청할까요? | M14: 요청 기록 + 승인 흐름 (목표 검토 요청 이력 저장 위치 신설 필요) | N14: 3 | O14: 3 | P14: 2 | Q14: =N14+O14+P14 | R14: 우리만 가능 | S14: 14일 | T14: 3건 이상 또는 팀의 30% 이상 | U14: 해당 팀의 미검토 비율이 30% 밑으로 내려가면 즉시 | V14: 목표 확정(승인) 기록과 시각이 현재 없음 — 신설 필요. 1차 평가자 매핑 필드 확인/신설 필요. 관측 대상은 팀원이 아니라 1차 평가자의 검토 행위. 억제: 팀원 개인의 목표 미작성 건은 1차에게만 뜨고, 2차에는 평가자 단위 합계로만 올린다
... A78: 피드백-HR경영진-04 | B78: 피드백 | C78: HR·경영진 | D78: ④ 서로 안 맞는다 | E78: 낮은 등급에 설명이 없는 조직이 있어요 | F78: 2개 조직 하위 등급 대상자 14명 중 개발 코멘트나 면담 기록이 남은 사람 2명 (전사 78%); 기준 시점 2026-07-16 | G78: 한 조직에서 하위 등급을 받은 사람 가운데 개발 코멘트나 면담 기록이 남지 않은 비율이 50% 이상이고 그 인원이 5명 이상일 때 | H78: 팀 평균 | I78: 평가의 등급; 평가 근거 요약문과 개발 코멘트; 다면 리뷰의 개발 코멘트; 면담 기록의 실시 여부; 대상자 소속조직 | J78: 조직별 하위 등급 인원과 코멘트 누락 건수; 인용할 수 있는 점검·다면 기록; 결과 면담 안내 문구 | K78: A6 요청하기 | L78: 이 조직에 결과 설명 면담과 개발 코멘트 보완을 요청할까요? | M78: 면담·코멘트 보완 요청 기록 + 조직별 이행 상태 — 요청 처리 원장과 면담 기록 서버 보존 신설 필요 | N78: 3 | O78: 2 | P78: 3 | Q78: =N78+O78+P78 | R78: 우리만 가능 | S78: 14일 | T78: 조직·전사 합계 기준 조직당 대상 5명 이상 또는 그 조직 하위 등급 인원의 50% 이상 | U78: 해당 조직의 코멘트 누락이 기준 아래로 줄어들거나 면담 기록이 등록되면 | V78: 등급은 평가 221건에 있으나 개발 코멘트는 다면 리뷰 55건(13명)에만 있고 면담 기록은 브라우저 80건 롤링이라 두 원천의 서버 보존과 연결 확인 필요. 개인 이름은 카드에 노출하지 않고 조직 단위 건수만 보여준다. 조직장(1차)이 팀원별 면담 카드를 먼저 받는다는 전제

Sheet 02_칸점검
B2: 02 칸 점검 — 16칸이 얼마나 채워졌나
B3: 4단계 × 4주체 = 16칸. 칸별 목표 = 기초 1개 + 우리만 가능한 것 1개 이상. 숫자는 01_신호목록에서 자동 집계된다(제외 판정은 세지 않는다).
B5: 단계 \ 주체 | C5: 조직원 | F5: 조직장(1차) | I5: 조직장(2차) | L5: HR·경영진
C6: 건수 | D6: 기초 | E6: 우리만 | F6: 건수 | G6: 기초 | H6: 우리만 | I6: 건수 | J6: 기초 | K6: 우리만 | L6: 건수 | M6: 기초 | N6: 우리만 | O6: 미달 칸
B7: 목표수립 | C7: =COUNTIFS('01_신호목록'!B3:B78,"목표수립",'01_신호목록'!C3:C78,"조직원",'01_신호목록'!R3:R78,"<>제외") | D7: =COUNTIFS('01_신호목록'!B3:B78,"목표수립",'01_신호목록'!C3:C78,"조직원",'01_신호목록'!R3:R78,"기초") | E7: =COUNTIFS('01_신호목록'!B3:B78,"목표수립",'01_신호목록'!C3:C78,"조직원",'01_신호목록'!R3:R78,"우리만 가능") | F7: =COUNTIFS('01_신호목록'!B3:B78,"목표수립",'01_신호목록'!C3:C78,"조직장(1차)",'01_신호목록'!R3:R78,"<>제외") | G7: =COUNTIFS('01_신호목록'!B3:B78,"목표수립",'01_신호목록'!C3:C78,"조직장(1차)",'01_신호목록'!R3:R78,"기초") | H7: =COUNTIFS('01_신호목록'!B3:B78,"목표수립",'01_신호목록'!C3:C78,"조직장(1차)",'01_신호목록'!R3:R78,"우리만 가능") | I7: =COUNTIFS('01_신호목록'!B3:B78,"목표수립",'01_신호목록'!C3:C78,"조직장(2차)",'01_신호목록'!R3:R78,"<>제외") | J7: =COUNTIFS('01_신호목록'!B3:B78,"목표수립",'01_신호목록'!C3:C78,"조직장(2차)",'01_신호목록'!R3:R78,"기초") | K7: =COUNTIFS('01_신호목록'!B3:B78,"목표수립",'01_신호목록'!C3:C78,"조직장(2차)",'01_신호목록'!R3:R78,"우리만 가능") | L7: =COUNTIFS('01_신호목록'!B3:B78,"목표수립",'01_신호목록'!C3:C78,"HR·경영진",'01_신호목록'!R3:R78,"<>제외") | M7: =COUNTIFS('01_신호목록'!B3:B78,"목표수립",'01_신호목록'!C3:C78,"HR·경영진",'01_신호목록'!R3:R78,"기초") | N7: =COUNTIFS('01_신호목록'!B3:B78,"목표수립",'01_신호목록'!C3:C78,"HR·경영진",'01_신호목록'!R3:R78,"우리만 가능") | O7: =TRIM(CONCATENATE(IF(OR(D7=0,E7=0),"조직원 ",""),IF(OR(G7=0,H7=0),"조직장(1차) ",""),IF(OR(J7=0,K7=0),"조직장(2차) ",""),IF(OR(M7=0,N7=0),"HR·경영진 ","")))
B8: 중간점검 | C8: =COUNTIFS('01_신호목록'!B3:B78,"중간점검",'01_신호목록'!C3:C78,"조직원",'01_신호목록'!R3:R78,"<>제외") | D8: =COUNTIFS('01_신호목록'!B3:B78,"중간점검",'01_신호목록'!C3:C78,"조직원",'01_신호목록'!R3:R78,"기초") | E8: =COUNTIFS('01_신호목록'!B3:B78,"중간점검",'01_신호목록'!C3:C78,"조직원",'01_신호목록'!R3:R78,"우리만 가능") | F8: =COUNTIFS('01_신호목록'!B3:B78,"중간점검",'01_신호목록'!C3:C78,"조직장(1차)",'01_신호목록'!R3:R78,"<>제외") | G8: =COUNTIFS('01_신호목록'!B3:B78,"중간점검",'01_신호목록'!C3:C78,"조직장(1차)",'01_신호목록'!R3:R78,"기초") | H8: =COUNTIFS('01_신호목록'!B3:B78,"중간점검",'01_신호목록'!C3:C78,"조직장(1차)",'01_신호목록'!R3:R78,"우리만 가능") | I8: =COUNTIFS('01_신호목록'!B3:B78,"중간점검",'01_신호목록'!C3:C78,"조직장(2차)",'01_신호목록'!R3:R78,"<>제외") | J8: =COUNTIFS('01_신호목록'!B3:B78,"중간점검",'01_신호목록'!C3:C78,"조직장(2차)",'01_신호목록'!R3:R78,"기초") | K8: =COUNTIFS('01_신호목록'!B3:B78,"중간점검",'01_신호목록'!C3:C78,"조직장(2차)",'01_신호목록'!R3:R78,"우리만 가능") | L8: =COUNTIFS('01_신호목록'!B3:B78,"중간점검",'01_신호목록'!C3:C78,"HR·경영진",'01_신호목록'!R3:R78,"<>제외") | M8: =COUNTIFS('01_신호목록'!B3:B78,"중간점검",'01_신호목록'!C3:C78,"HR·경영진",'01_신호목록'!R3:R78,"기초") | N8: =COUNTIFS('01_신호목록'!B3:B78,"중간점검",'01_신호목록'!C3:C78,"HR·경영진",'01_신호목록'!R3:R78,"우리만 가능") | O8: =TRIM(CONCATENATE(IF(OR(D8=0,E8=0),"조직원 ",""),IF(OR(G8=0,H8=0),"조직장(1차) ",""),IF(OR(J8=0,K8=0),"조직장(2차) ",""),IF(OR(M8=0,N8=0),"HR·경영진 ","")))
B9: 평가 | C9: =COUNTIFS('01_신호목록'!B3:B78,"평가",'01_신호목록'!C3:C78,"조직원",'01_신호목록'!R3:R78,"<>제외") | D9: =COUNTIFS('01_신호목록'!B3:B78,"평가",'01_신호목록'!C3:C78,"조직원",'01_신호목록'!R3:R78,"기초") | E9: =COUNTIFS('01_신호목록'!B3:B78,"평가",'01_신호목록'!C3:C78,"조직원",'01_신호목록'!R3:R78,"우리만 가능") | F9: =COUNTIFS('01_신호목록'!B3:B78,"평가",'01_신호목록'!C3:C78,"조직장(1차)",'01_신호목록'!R3:R78,"<>제외") | G9: =COUNTIFS('01_신호목록'!B3:B78,"평가",'01_신호목록'!C3:C78,"조직장(1차)",'01_신호목록'!R3:R78,"기초") | H9: =COUNTIFS('01_신호목록'!B3:B78,"평가",'01_신호목록'!C3:C78,"조직장(1차)",'01_신호목록'!R3:R78,"우리만 가능") | I9: =COUNTIFS('01_신호목록'!B3:B78,"평가",'01_신호목록'!C3:C78,"조직장(2차)",'01_신호목록'!R3:R78,"<>제외") | J9: =COUNTIFS('01_신호목록'!B3:B78,"평가",'01_신호목록'!C3:C78,"조직장(2차)",'01_신호목록'!R3:R78,"기초") | K9: =COUNTIFS('01_신호목록'!B3:B78,"평가",'01_신호목록'!C3:C78,"조직장(2차)",'01_신호목록'!R3:R78,"우리만 가능") | L9: =COUNTIFS('01_신호목록'!B3:B78,"평가",'01_신호목록'!C3:C78,"HR·경영진",'01_신호목록'!R3:R78,"<>제외") | M9: =COUNTIFS('01_신호목록'!B3:B78,"평가",'01_신호목록'!C3:C78,"HR·경영진",'01_신호목록'!R3:R78,"기초") | N9: =COUNTIFS('01_신호목록'!B3:B78,"평가",'01_신호목록'!C3:C78,"HR·경영진",'01_신호목록'!R3:R78,"우리만 가능") | O9: =TRIM(CONCATENATE(IF(OR(D9=0,E9=0),"조직원 ",""),IF(OR(G9=0,H9=0),"조직장(1차) ",""),IF(OR(J9=0,K9=0),"조직장(2차) ",""),IF(OR(M9=0,N9=0),"HR·경영진 ","")))
B10: 피드백 | C10: =COUNTIFS('01_신호목록'!B3:B78,"피드백",'01_신호목록'!C3:C78,"조직원",'01_신호목록'!R3:R78,"<>제외") | D10: =COUNTIFS('01_신호목록'!B3:B78,"피드백",'01_신호목록'!C3:C78,"조직원",'01_신호목록'!R3:R78,"기초") | E10: =COUNTIFS('01_신호목록'!B3:B78,"피드백",'01_신호목록'!C3:C78,"조직원",'01_신호목록'!R3:R78,"우리만 가능") | F10: =COUNTIFS('01_신호목록'!B3:B78,"피드백",'01_신호목록'!C3:C78,"조직장(1차)",'01_신호목록'!R3:R78,"<>제외") | G10: =COUNTIFS('01_신호목록'!B3:B78,"피드백",'01_신호목록'!C3:C78,"조직장(1차)",'01_신호목록'!R3:R78,"기초") | H10: =COUNTIFS('01_신호목록'!B3:B78,"피드백",'01_신호목록'!C3:C78,"조직장(1차)",'01_신호목록'!R3:R78,"우리만 가능") | I10: =COUNTIFS('01_신호목록'!B3:B78,"피드백",'01_신호목록'!C3:C78,"조직장(2차)",'01_신호목록'!R3:R78,"<>제외") | J10: =COUNTIFS('01_신호목록'!B3:B78,"피드백",'01_신호목록'!C3:C78,"조직장(2차)",'01_신호목록'!R3:R78,"기초") | K10: =COUNTIFS('01_신호목록'!B3:B78,"피드백",'01_신호목록'!C3:C78,"조직장(2차)",'01_신호목록'!R3:R78,"우리만 가능") | L10: =COUNTIFS('01_신호목록'!B3:B78,"피드백",'01_신호목록'!C3:C78,"HR·경영진",'01_신호목록'!R3:R78,"<>제외") | M10: =COUNTIFS('01_신호목록'!B3:B78,"피드백",'01_신호목록'!C3:C78,"HR·경영진",'01_신호목록'!R3:R78,"기초") | N10: =COUNTIFS('01_신호목록'!B3:B78,"피드백",'01_신호목록'!C3:C78,"HR·경영진",'01_신호목록'!R3:R78,"우리만 가능") | O10: =TRIM(CONCATENATE(IF(OR(D10=0,E10=0),"조직원 ",""),IF(OR(G10=0,H10=0),"조직장(1차) ",""),IF(OR(J10=0,K10=0),"조직장(2차) ",""),IF(OR(M10=0,N10=0),"HR·경영진 ","")))
B12: 기초 또는 우리만 가능이 0인 칸은 "미달 칸"에 주체 이름이 뜬다. 그 칸은 아래 "빈칸 사유"에 왜 비었는지가 적혀 있어야 한다.
B14: 80 스캔포인트 — 16칸 × 변화 5유형을 훑은 결과
B15: 숫자 = 채택된 알림 수. 0은 훑었으나 만들지 않았다는 뜻이며, 사유는 아래 표에 있다.
B16: 단계 | C16: 주체 | D16: ①때가됐다 | E16: ②비어있다 | F16: ③기준이탈 | G16: ④안맞는다 | H16: ⑤일이생겼다 | I16: 소계
B17: 목표수립 | C17: 조직원 | D17: =COUNTIFS('01_신호목록'!B3:B78,"목표수립",'01_신호목록'!C3:C78,"조직원",'01_신호목록'!D3:D78,"① 때가 됐다",'01_신호목록'!R3:R78,"<>제외") | E17: =COUNTIFS('01_신호목록'!B3:B78,"목표수립",'01_신호목록'!C3:C78,"조직원",'01_신호목록'!D3:D78,"② 비어 있다 / 멈췄다",'01_신호목록'!R3:R78,"<>제외") | F17: =COUNTIFS('01_신호목록'!B3:B78,"목표수립",'01_신호목록'!C3:C78,"조직원",'01_신호목록'!D3:D78,"③ 기준을 벗어났다",'01_신호목록'!R3:R78,"<>제외") | G17: =COUNTIFS('01_신호목록'!B3:B78,"목표수립",'01_신호목록'!C3:C78,"조직원",'01_신호목록'!D3:D78,"④ 서로 안 맞는다",'01_신호목록'!R3:R78,"<>제외") | H17: =COUNTIFS('01_신호목록'!B3:B78,"목표수립",'01_신호목록'!C3:C78,"조직원",'01_신호목록'!D3:D78,"⑤ 무슨 일이 생겼다",'01_신호목록'!R3:R78,"<>제외") | I17: =SUM(D17:H17)
B18: 목표수립 | C18: 조직장(1차) | D18: =COUNTIFS('01_신호목록'!B3:B78,"목표수립",'01_신호목록'!C3:C78,"조직장(1차)",'01_신호목록'!D3:D78,"① 때가 됐다",'01_신호목록'!R3:R78,"<>제외") | E18: =COUNTIFS('01_신호목록'!B3:B78,"목표수립",'01_신호목록'!C3:C78,"조직장(1차)",'01_신호목록'!D3:D78,"② 비어 있다 / 멈췄다",'01_신호목록'!R3:R78,"<>제외") | F18: =COUNTIFS('01_신호목록'!B3:B78,"목표수립",'01_신호목록'!C3:C78,"조직장(1차)",'01_신호목록'!D3:D78,"③ 기준을 벗어났다",'01_신호목록'!R3:R78,"<>제외") | G18: =COUNTIFS('01_신호목록'!B3:B78,"목표수립",'01_신호목록'!C3:C78,"조직장(1차)",'01_신호목록'!D3:D78,"④ 서로 안 맞는다",'01_신호목록'!R3:R78,"<>제외") | H18: =COUNTIFS('01_신호목록'!B3:B78,"목표수립",'01_신호목록'!C3:C78,"조직장(1차)",'01_신호목록'!D3:D78,"⑤ 무슨 일이 생겼다",'01_신호목록'!R3:R78,"<>제외") | I18: =SUM(D18:H18)
B19: 목표수립 | C19: 조직장(2차) | D19: =COUNTIFS('01_신호목록'!B3:B78,"목표수립",'01_신호목록'!C3:C78,"조직장(2차)",'01_신호목록'!D3:D78,"① 때가 됐다",'01_신호목록'!R3:R78,"<>제외") | E19: =COUNTIFS('01_신호목록'!B3:B78,"목표수립",'01_신호목록'!C3:C78,"조직장(2차)",'01_신호목록'!D3:D78,"② 비어 있다 / 멈췄다",'01_신호목록'!R3:R78,"<>제외") | F19: =COUNTIFS('01_신호목록'!B3:B78,"목표수립",'01_신호목록'!C3:C78,"조직장(2차)",'01_신호목록'!D3:D78,"③ 기준을 벗어났다",'01_신호목록'!R3:R78,"<>제외") | G19: =COUNTIFS('01_신호목록'!B3:B78,"목표수립",'01_신호목록'!C3:C78,"조직장(2차)",'01_신호목록'!D3:D78,"④ 서로 안 맞는다",'01_신호목록'!R3:R78,"<>제외") | H19: =COUNTIFS('01_신호목록'!B3:B78,"목표수립",'01_신호목록'!C3:C78,"조직장(2차)",'01_신호목록'!D3:D78,"⑤ 무슨 일이 생겼다",'01_신호목록'!R3:R78,"<>제외") | I19: =SUM(D19:H19)
B20: 목표수립 | C20: HR·경영진 | D20: =COUNTIFS('01_신호목록'!B3:B78,"목표수립",'01_신호목록'!C3:C78,"HR·경영진",'01_신호목록'!D3:D78,"① 때가 됐다",'01_신호목록'!R3:R78,"<>제외") | E20: =COUNTIFS('01_신호목록'!B3:B78,"목표수립",'01_신호목록'!C3:C78,"HR·경영진",'01_신호목록'!D3:D78,"② 비어 있다 / 멈췄다",'01_신호목록'!R3:R78,"<>제외") | F20: =COUNTIFS('01_신호목록'!B3:B78,"목표수립",'01_신호목록'!C3:C78,"HR·경영진",'01_신호목록'!D3:D78,"③ 기준을 벗어났다",'01_신호목록'!R3:R78,"<>제외") | G20: =COUNTIFS('01_신호목록'!B3:B78,"목표수립",'01_신호목록'!C3:C78,"HR·경영진",'01_신호목록'!D3:D78,"④ 서로 안 맞는다",'01_신호목록'!R3:R78,"<>제외") | H20: =COUNTIFS('01_신호목록'!B3:B78,"목표수립",'01_신호목록'!C3:C78,"HR·경영진",'01_신호목록'!D3:D78,"⑤ 무슨 일이 생겼다",'01_신호목록'!R3:R78,"<>제외") | I20: =SUM(D20:H20)
B21: 중간점검 | C21: 조직원 | D21: =COUNTIFS('01_신호목록'!B3:B78,"중간점검",'01_신호목록'!C3:C78,"조직원",'01_신호목록'!D3:D78,"① 때가 됐다",'01_신호목록'!R3:R78,"<>제외") | E21: =COUNTIFS('01_신호목록'!B3:B78,"중간점검",'01_신호목록'!C3:C78,"조직원",'01_신호목록'!D3:D78,"② 비어 있다 / 멈췄다",'01_신호목록'!R3:R78,"<>제외") | F21: =COUNTIFS('01_신호목록'!B3:B78,"중간점검",'01_신호목록'!C3:C78,"조직원",'01_신호목록'!D3:D78,"③ 기준을 벗어났다",'01_신호목록'!R3:R78,"<>제외") | G21: =COUNTIFS('01_신호목록'!B3:B78,"중간점검",'01_신호목록'!C3:C78,"조직원",'01_신호목록'!D3:D78,"④ 서로 안 맞는다",'01_신호목록'!R3:R78,"<>제외") | H21: =COUNTIFS('01_신호목록'!B3:B78,"중간점검",'01_신호목록'!C3:C78,"조직원",'01_신호목록'!D3:D78,"⑤ 무슨 일이 생겼다",'01_신호목록'!R3:R78,"<>제외") | I21: =SUM(D21:H21)
B22: 중간점검 | C22: 조직장(1차) | D22: =COUNTIFS('01_신호목록'!B3:B78,"중간점검",'01_신호목록'!C3:C78,"조직장(1차)",'01_신호목록'!D3:D78,"① 때가 됐다",'01_신호목록'!R3:R78,"<>제외") | E22: =COUNTIFS('01_신호목록'!B3:B78,"중간점검",'01_신호목록'!C3:C78,"조직장(1차)",'01_신호목록'!D3:D78,"② 비어 있다 / 멈췄다",'01_신호목록'!R3:R78,"<>제외") | F22: =COUNTIFS('01_신호목록'!B3:B78,"중간점검",'01_신호목록'!C3:C78,"조직장(1차)",'01_신호목록'!D3:D78,"③ 기준을 벗어났다",'01_신호목록'!R3:R78,"<>제외") | G22: =COUNTIFS('01_신호목록'!B3:B78,"중간점검",'01_신호목록'!C3:C78,"조직장(1차)",'01_신호목록'!D3:D78,"④ 서로 안 맞는다",'01_신호목록'!R3:R78,"<>제외") | H22: =COUNTIFS('01_신호목록'!B3:B78,"중간점검",'01_신호목록'!C3:C78,"조직장(1차)",'01_신호목록'!D3:D78,"⑤ 무슨 일이 생겼다",'01_신호목록'!R3:R78,"<>제외") | I22: =SUM(D22:H22)
B23: 중간점검 | C23: 조직장(2차) | D23: =COUNTIFS('01_신호목록'!B3:B78,"중간점검",'01_신호목록'!C3:C78,"조직장(2차)",'01_신호목록'!D3:D78,"① 때가 됐다",'01_신호목록'!R3:R78,"<>제외") | E23: =COUNTIFS('01_신호목록'!B3:B78,"중간점검",'01_신호목록'!C3:C78,"조직장(2차)",'01_신호목록'!D3:D78,"② 비어 있다 / 멈췄다",'01_신호목록'!R3:R78,"<>제외") | F23: =COUNTIFS('01_신호목록'!B3:B78,"중간점검",'01_신호목록'!C3:C78,"조직장(2차)",'01_신호목록'!D3:D78,"③ 기준을 벗어났다",'01_신호목록'!R3:R78,"<>제외") | G23: =COUNTIFS('01_신호목록'!B3:B78,"중간점검",'01_신호목록'!C3:C78,"조직장(2차)",'01_신호목록'!D3:D78,"④ 서로 안 맞는다",'01_신호목록'!R3:R78,"<>제외") | H23: =COUNTIFS('01_신호목록'!B3:B78,"중간점검",'01_신호목록'!C3:C78,"조직장(2차)",'01_신호목록'!D3:D78,"⑤ 무슨 일이 생겼다",'01_신호목록'!R3:R78,"<>제외") | I23: =SUM(D23:H23)
B24: 중간점검 | C24: HR·경영진 | D24: =COUNTIFS('01_신호목록'!B3:B78,"중간점검",'01_신호목록'!C3:C78,"HR·경영진",'01_신호목록'!D3:D78,"① 때가 됐다",'01_신호목록'!R3:R78,"<>제외") | E24: =COUNTIFS('01_신호목록'!B3:B78,"중간점검",'01_신호목록'!C3:C78,"HR·경영진",'01_신호목록'!D3:D78,"② 비어 있다 / 멈췄다",'01_신호목록'!R3:R78,"<>제외") | F24: =COUNTIFS('01_신호목록'!B3:B78,"중간점검",'01_신호목록'!C3:C78,"HR·경영진",'01_신호목록'!D3:D78,"③ 기준을 벗어났다",'01_신호목록'!R3:R78,"<>제외") | G24: =COUNTIFS('01_신호목록'!B3:B78,"중간점검",'01_신호목록'!C3:C78,"HR·경영진",'01_신호목록'!D3:D78,"④ 서로 안 맞는다",'01_신호목록'!R3:R78,"<>제외") | H24: =COUNTIFS('01_신호목록'!B3:B78,"중간점검",'01_신호목록'!C3:C78,"HR·경영진",'01_신호목록'!D3:D78,"⑤ 무슨 일이 생겼다",'01_신호목록'!R3:R78,"<>제외") | I24: =SUM(D24:H24)
B25: 평가 | C25: 조직원 | D25: =COUNTIFS('01_신호목록'!B3:B78,"평가",'01_신호목록'!C3:C78,"조직원",'01_신호목록'!D3:D78,"① 때가 됐다",'01_신호목록'!R3:R78,"<>제외") | E25: =COUNTIFS('01_신호목록'!B3:B78,"평가",'01_신호목록'!C3:C78,"조직원",'01_신호목록'!D3:D78,"② 비어 있다 / 멈췄다",'01_신호목록'!R3:R78,"<>제외") | F25: =COUNTIFS('01_신호목록'!B3:B78,"평가",'01_신호목록'!C3:C78,"조직원",'01_신호목록'!D3:D78,"③ 기준을 벗어났다",'01_신호목록'!R3:R78,"<>제외") | G25: =COUNTIFS('01_신호목록'!B3:B78,"평가",'01_신호목록'!C3:C78,"조직원",'01_신호목록'!D3:D78,"④ 서로 안 맞는다",'01_신호목록'!R3:R78,"<>제외") | H25: =COUNTIFS('01_신호목록'!B3:B78,"평가",'01_신호목록'!C3:C78,"조직원",'01_신호목록'!D3:D78,"⑤ 무슨 일이 생겼다",'01_신호목록'!R3:R78,"<>제외") | I25: =SUM(D25:H25)
B26: 평가 | C26: 조직장(1차) | D26: =COUNTIFS('01_신호목록'!B3:B78,"평가",'01_신호목록'!C3:C78,"조직장(1차)",'01_신호목록'!D3:D78,"① 때가 됐다",'01_신호목록'!R3:R78,"<>제외") | E26: =COUNTIFS('01_신호목록'!B3:B78,"평가",'01_신호목록'!C3:C78,"조직장(1차)",'01_신호목록'!D3:D78,"② 비어 있다 / 멈췄다",'01_신호목록'!R3:R78,"<>제외") | F26: =COUNTIFS('01_신호목록'!B3:B78,"평가",'01_신호목록'!C3:C78,"조직장(1차)",'01_신호목록'!D3:D78,"③ 기준을 벗어났다",'01_신호목록'!R3:R78,"<>제외") | G26: =COUNTIFS('01_신호목록'!B3:B78,"평가",'01_신호목록'!C3:C78,"조직장(1차)",'01_신호목록'!D3:D78,"④ 서로 안 맞는다",'01_신호목록'!R3:R78,"<>제외") | H26: =COUNTIFS('01_신호목록'!B3:B78,"평가",'01_신호목록'!C3:C78,"조직장(1차)",'01_신호목록'!D3:D78,"⑤ 무슨 일이 생겼다",'01_신호목록'!R3:R78,"<>제외") | I26: =SUM(D26:H26)
B27: 평가 | C27: 조직장(2차) | D27: =COUNTIFS('01_신호목록'!B3:B78,"평가",'01_신호목록'!C3:C78,"조직장(2차)",'01_신호목록'!D3:D78,"① 때가 됐다",'01_신호목록'!R3:R78,"<>제외") | E27: =COUNTIFS('01_신호목록'!B3:B78,"평가",'01_신호목록'!C3:C78,"조직장(2차)",'01_신호목록'!D3:D78,"② 비어 있다 / 멈췄다",'01_신호목록'!R3:R78,"<>제외") | F27: =COUNTIFS('01_신호목록'!B3:B78,"평가",'01_신호목록'!C3:C78,"조직장(2차)",'01_신호목록'!D3:D78,"③ 기준을 벗어났다",'01_신호목록'!R3:R78,"<>제외") | G27: =COUNTIFS('01_신호목록'!B3:B78,"평가",'01_신호목록'!C3:C78,"조직장(2차)",'01_신호목록'!D3:D78,"④ 서로 안 맞는다",'01_신호목록'!R3:R78,"<>제외") | H27: =COUNTIFS('01_신호목록'!B3:B78,"평가",'01_신호목록'!C3:C78,"조직장(2차)",'01_신호목록'!D3:D78,"⑤ 무슨 일이 생겼다",'01_신호목록'!R3:R78,"<>제외") | I27: =SUM(D27:H27)
B28: 평가 | C28: HR·경영진 | D28: =COUNTIFS('01_신호목록'!B3:B78,"평가",'01_신호목록'!C3:C78,"HR·경영진",'01_신호목록'!D3:D78,"① 때가 됐다",'01_신호목록'!R3:R78,"<>제외") | E28: =COUNTIFS('01_신호목록'!B3:B78,"평가",'01_신호목록'!C3:C78,"HR·경영진",'01_신호목록'!D3:D78,"② 비어 있다 / 멈췄다",'01_신호목록'!R3:R78,"<>제외") | F28: =COUNTIFS('01_신호목록'!B3:B78,"평가",'01_신호목록'!C3:C78,"HR·경영진",'01_신호목록'!D3:D78,"③ 기준을 벗어났다",'01_신호목록'!R3:R78,"<>제외") | G28: =COUNTIFS('01_신호목록'!B3:B78,"평가",'01_신호목록'!C3:C78,"HR·경영진",'01_신호목록'!D3:D78,"④ 서로 안 맞는다",'01_신호목록'!R3:R78,"<>제외") | H28: =COUNTIFS('01_신호목록'!B3:B78,"평가",'01_신호목록'!C3:C78,"HR·경영진",'01_신호목록'!D3:D78,"⑤ 무슨 일이 생겼다",'01_신호목록'!R3:R78,"<>제외") | I28: =SUM(D28:H28)
B29: 피드백 | C29: 조직원 | D29: =COUNTIFS('01_신호목록'!B3:B78,"피드백",'01_신호목록'!C3:C78,"조직원",'01_신호목록'!D3:D78,"① 때가 됐다",'01_신호목록'!R3:R78,"<>제외") | E29: =COUNTIFS('01_신호목록'!B3:B78,"피드백",'01_신호목록'!C3:C78,"조직원",'01_신호목록'!D3:D78,"② 비어 있다 / 멈췄다",'01_신호목록'!R3:R78,"<>제외") | F29: =COUNTIFS('01_신호목록'!B3:B78,"피드백",'01_신호목록'!C3:C78,"조직원",'01_신호목록'!D3:D78,"③ 기준을 벗어났다",'01_신호목록'!R3:R78,"<>제외") | G29: =COUNTIFS('01_신호목록'!B3:B78,"피드백",'01_신호목록'!C3:C78,"조직원",'01_신호목록'!D3:D78,"④ 서로 안 맞는다",'01_신호목록'!R3:R78,"<>제외") | H29: =COUNTIFS('01_신호목록'!B3:B78,"피드백",'01_신호목록'!C3:C78,"조직원",'01_신호목록'!D3:D78,"⑤ 무슨 일이 생겼다",'01_신호목록'!R3:R78,"<>제외") | I29: =SUM(D29:H29)
B30: 피드백 | C30: 조직장(1차) | D30: =COUNTIFS('01_신호목록'!B3:B78,"피드백",'01_신호목록'!C3:C78,"조직장(1차)",'01_신호목록'!D3:D78,"① 때가 됐다",'01_신호목록'!R3:R78,"<>제외") | E30: =COUNTIFS('01_신호목록'!B3:B78,"피드백",'01_신호목록'!C3:C78,"조직장(1차)",'01_신호목록'!D3:D78,"② 비어 있다 / 멈췄다",'01_신호목록'!R3:R78,"<>제외") | F30: =COUNTIFS('01_신호목록'!B3:B78,"피드백",'01_신호목록'!C3:C78,"조직장(1차)",'01_신호목록'!D3:D78,"③ 기준을 벗어났다",'01_신호목록'!R3:R78,"<>제외") | G30: =COUNTIFS('01_신호목록'!B3:B78,"피드백",'01_신호목록'!C3:C78,"조직장(1차)",'01_신호목록'!D3:D78,"④ 서로 안 맞는다",'01_신호목록'!R3:R78,"<>제외") | H30: =COUNTIFS('01_신호목록'!B3:B78,"피드백",'01_신호목록'!C3:C78,"조직장(1차)",'01_신호목록'!D3:D78,"⑤ 무슨 일이 생겼다",'01_신호목록'!R3:R78,"<>제외") | I30: =SUM(D30:H30)
B31: 피드백 | C31: 조직장(2차) | D31: =COUNTIFS('01_신호목록'!B3:B78,"피드백",'01_신호목록'!C3:C78,"조직장(2차)",'01_신호목록'!D3:D78,"① 때가 됐다",'01_신호목록'!R3:R78,"<>제외") | E31: =COUNTIFS('01_신호목록'!B3:B78,"피드백",'01_신호목록'!C3:C78,"조직장(2차)",'01_신호목록'!D3:D78,"② 비어 있다 / 멈췄다",'01_신호목록'!R3:R78,"<>제외") | F31: =COUNTIFS('01_신호목록'!B3:B78,"피드백",'01_신호목록'!C3:C78,"조직장(2차)",'01_신호목록'!D3:D78,"③ 기준을 벗어났다",'01_신호목록'!R3:R78,"<>제외") | G31: =COUNTIFS('01_신호목록'!B3:B78,"피드백",'01_신호목록'!C3:C78,"조직장(2차)",'01_신호목록'!D3:D78,"④ 서로 안 맞는다",'01_신호목록'!R3:R78,"<>제외") | H31: =COUNTIFS('01_신호목록'!B3:B78,"피드백",'01_신호목록'!C3:C78,"조직장(2차)",'01_신호목록'!D3:D78,"⑤ 무슨 일이 생겼다",'01_신호목록'!R3:R78,"<>제외") | I31: =SUM(D31:H31)
B32: 피드백 | C32: HR·경영진 | D32: =COUNTIFS('01_신호목록'!B3:B78,"피드백",'01_신호목록'!C3:C78,"HR·경영진",'01_신호목록'!D3:D78,"① 때가 됐다",'01_신호목록'!R3:R78,"<>제외") | E32: =COUNTIFS('01_신호목록'!B3:B78,"피드백",'01_신호목록'!C3:C78,"HR·경영진",'01_신호목록'!D3:D78,"② 비어 있다 / 멈췄다",'01_신호목록'!R3:R78,"<>제외") | F32: =COUNTIFS('01_신호목록'!B3:B78,"피드백",'01_신호목록'!C3:C78,"HR·경영진",'01_신호목록'!D3:D78,"③ 기준을 벗어났다",'01_신호목록'!R3:R78,"<>제외") | G32: =COUNTIFS('01_신호목록'!B3:B78,"피드백",'01_신호목록'!C3:C78,"HR·경영진",'01_신호목록'!D3:D78,"④ 서로 안 맞는다",'01_신호목록'!R3:R78,"<>제외") | H32: =COUNTIFS('01_신호목록'!B3:B78,"피드백",'01_신호목록'!C3:C78,"HR·경영진",'01_신호목록'!D3:D78,"⑤ 무슨 일이 생겼다",'01_신호목록'!R3:R78,"<>제외") | I32: =SUM(D32:H32)
B35: 빈칸 사유 — 왜 만들지 않았나 (11건)
B36: 억지로 채우지 않는다. 빈칸이 남는 건 결과이며, 왜 비었는지가 다음 단계의 할 일 목록이 된다.
B37: 주체 | C37: 단계 | D37: 변화의 종류 | E37: 왜 비었는지
B38: 조직원 | C38: 중간점검 | D38: ① 때가 됐다 | E38: 점검 자체의 기한이 제도 일정에 없고, 기한을 만들어도 '며칠째 비어 있다'(②)와 원인이 같아 같은 사람에게 두 번 뜨는 알림이 된다
B39: 조직원 | C39: 피드백 | D39: ② 비어 있다 / 멈췄다 | E39: 받은 피드백을 열었는지·답했는지가 어디에도 남지 않아 '며칠째 그대로다'를 규칙으로 판정할 수 없다
B40: 조직원 | C40: 피드백 | D40: ③ 기준을 벗어났다 | E40: 개인이 받은 피드백 건수로 기준선을 만들 만한 모수가 없다 (받은 피드백 7건·상향 피드백 2건)
B41: 조직장(1차) | C41: 중간점검 | D41: ④ 서로 안 맞는다 | E41: 팀원 목표가 팀 목표·직무와 어긋나는 건은 목표수립-조직장1차-04와 원인이 같아, 중간점검에서 다시 띄우면 같은 사람에게 같은 카드가 두 번 뜬다
B42: 조직장(1차) | C42: 평가 | D42: ② 비어 있다 / 멈췄다 | E42: 평가 레코드에 최종 수정 일시가 없고 자기평가 제출도 임시 저장뿐이어서, 평가가 '며칠째 그대로'인지를 규칙으로 판정할 수 없다
B43: 조직장(1차) | C43: 피드백 | D43: ③ 기준을 벗어났다 | E43: 팀원별로 받은 피드백이 전사 7건·상향 피드백 2건뿐이어서 많다·적다를 가릴 기준선을 만들 모수가 없다
B44: 조직장(1차) | C44: 피드백 | D44: ④ 서로 안 맞는다 | E44: 확정 등급과 전달할 피드백 문장의 어긋남은 평가-조직장1차-03과 원인이 같고, 피드백 초안이 저장되지 않아 비교할 대상 자체가 없다
B45: 조직장(2차) | C45: 피드백 | D45: ③ 기준을 벗어났다 | E45: 팀별 피드백 지표로 기준선을 만들 모수가 없다 — 받은 피드백 7건·상향 피드백 2건이고 전달·열람 기록이 아예 없어 팀 합계 최소 건수(3건 또는 팀의 30%)를 판정할 수 없다. 피드백 전달·열람 기록이 신설된 뒤 재검토
B46: HR·경영진 | C46: 중간점검 | D46: ② 비어 있다 / 멈췄다 | E46: 점검이 멈춘 개별 건은 조직원과 조직장(1차)이 먼저 처리할 기회를 갖고, HR·경영진에게는 ③ 참여율·진척 미달 카드로 이미 합쳐 뜬다. 같은 원인을 다시 올리면 볼 것만 늘고 할 일은 겹친다
...

Sheet 03_문장·기록규칙
B2: 03 문장 쓰는 규칙 · 알림 기록으로 남길 항목
B3: 규칙 버전 v0.1 (2026-07-28) — 규칙을 고치면 이 버전을 올린다. 그래야 알림 기록에서 고친 전후를 비교할 수 있다.
B6: (1) 문장 쓰는 규칙 | C6: — 여러 사람이 나눠 써도 알림 말투가 하나로 유지되게 하는 기준
B7: 항목 | C7: 규칙 | D7: 이렇게 쓰지 말고 | E7: 이렇게
B8: 신호 문장 (E열) | C8: 본 것을 그대로 말하는 구어체. 12~24자 | D8: 미제출 2건 발생 | E8: 팀원 2명이 목표를 아직 안 세웠어요
B9: 주체 표시 | C9: 누가·무엇이 달라졌는지 문장에 넣는다 | D9: 진척 정체 감지 | E9: 팀원 B님 진척이 2주째 멈췄어요
B10: 단정적 평가 금지 | C10: "문제·위험·이상" 같은 판정어를 쓰지 않는다 | D10: 목표 정렬에 위험이 있습니다 | E10: 목표가 팀 방향과 조금 어긋나 있어요
B11: AI 자기소개 금지 | C11: AI가 분석했다는 말을 넣지 않는다 | D11: AI가 분석한 결과입니다 | E11: (문장에서 뺀다)
B12: 확률·정확도 금지 | C12: 숫자로 된 신뢰도를 노출하지 않는다 | D12: 이탈 확률 78% | E12: 체크인율이 크게 낮아진 팀이 있어요
B13: 사과 문구 금지 | C13: 알림이 사과하지 않는다 | D13: 번거롭게 해드려 죄송하지만 | E13: (문장에서 뺀다)
B14: 애매하면 안 띄운다 | C14: 근거가 부족하면 알림을 만들지 않는다 | D14: 잘 모르겠지만 확인이 필요해요 | E14: (알림을 만들지 않는다)
B15: 물어보는 문장 (L열) | C15: 한 번에 하나만 묻는다. 확정 버튼은 사람이 누른다 | D15: 전부 처리해 드릴까요? | E15: 이대로 진행 점검할까요?
B18: 근거 쓰는 규칙 4가지
B19: 항목 | C19: 내용 | D19: 이렇게 쓰지 말고 | E19: 이렇게
B20: 한 줄에 한 사실 | C20: 근거 한 줄 = 사실 하나 + 출처 하나 | D20: 진척이 낮다 | E20: 핵심결과 "전환율 개선" 진척 42%
B21: 비교 기준 붙이기 | C21: 숫자만 있으면 이상한지 알 수 없다 | D21: 42% | E21: 42% (팀 평균 71%)
B22: 언제 기준인지 쓰기 | C22: 모든 근거에 기준 시점을 붙인다 | D22: 현재 진척 42% | E22: 7월 16일 기준 진척 42%
B23: 3~5줄 | C23: 그보다 길면 접어 둔다 | D23: 근거 10줄 나열 | E23: 핵심 3줄 + 나머지는 접기
B25: 비교 기준은 4가지 중 하나를 골라 적는다 — ① 본인의 예전 기록 ② 같은 팀·같은 직무 평균 ③ 계획 대비 ④ 제도 기준값. 근거 한 줄마다 어느 기록에서 나온 것인지(목표 번호·핵심결과 번호·점검 번호)를 함께 적는다. 나중에 확인하는 일, 알림 기록과 맞춰 보는 일, 알림에서 해당 화면으로 바로 넘어가는 기능이 전부 이 표시에서 나온다.
B28: (2) 알림 기록으로 남길 항목 | C28: — 규칙으로 만든 알림은 나중에 성적을 봐야 고칠 수 있다
B29: 묶음 | C29: 남길 것 | D29: 여기서 알 수 있는 것
B30: ① 떴을 때 | C30: 알림 번호, 규칙 버전, 뜬 시각, 어느 시점 기준인지(as-of) | D30: 규칙을 고쳤을 때 전보다 나아졌는지
B31: ② 누구에게 | C31: 대상자, 주체 구분, 범위(본인/팀원/팀/조직) | D31: 주체별로 알림이 몇 개씩 가는지
B32: ③ 무엇을 보고 | C32: 변화의 종류, 본 기록(목표·핵심결과·점검·평가 번호), 판단 결과값 | D32: 어떤 종류가 헛알림이 많은지
B33: ④ 근거 | C33: 사실·숫자·비교 기준·출처·기준 시점 | D33: 근거를 펼쳐 보는 비율
B34: ⑤ 행동과 결과 | C34: 행동 종류, 초안 생성 여부, 보낸 시각, 열어본 시각, 결과(확정/고쳐서 확정/무시/기한 지남), 저장된 기록 번호 | D34: 확정 비율, 고쳐서 확정한 비율, 무시 비율, 열고도 아무것도 안 한 비율
B35: ⑥ 안 띄운 경우 | C35: 안 띄운 이유(재알림 간격·상위 흡수·최소 건수 미달), 다시 띄울 수 있는 시각, 대신 뜬 상위 알림 번호 | D35: 알림을 잘 줄이고 있는지
B37: 생성형 AI는 문장을 고쳐서 성능을 올릴 수 있지만 규칙은 그렇게 못 한다. 어떤 알림이 열리고, 실제로 처리되고, 무시되는지를 남기지 않으면 규칙은 첫 버전에 그대로 머문다. 현재 데모에서는 알림 기록이 브라우저에 50건만 남고 원천이 두 계통으로 갈라져 있어, 이 표대로 남기려면 서버 보존 원장을 새로 만들어야 한다.
B40: ⑤에서 읽는 신호
B41: 수치 | C41: 낮거나 높으면
B42: 열어본 비율이 낮음 | C42: 문장이 안 끌리거나 알림 채널이 안 맞음
B43: 근거를 펼쳐 본 비율이 낮음 | C43: 근거를 볼 필요 없는 알림 = 굳이 없어도 되는 알림
B44: 고쳐서 확정한 비율이 높음 | C44: 초안 재료(J열)가 부족함
B45: 무시 비율이 높음 | C45: 띄우는 조건이 너무 예민함
B46: 열고도 아무것도 안 한 비율이 높음 | C46: 무엇을 해야 하는지가 불분명함
B49: 개발자에게 넘길 때 보는 곳
B50: 무엇을 만들 때 | C50: 어느 열을 보나
B51: 알림을 띄울지 판단하는 규칙 | C51: G(판단 조건) · H(비교 기준) · D(변화의 종류)
B52: 어떤 정보를 읽어야 하는지 | C52: I(필요한 정보) · J(초안 재료)
B53: 누구에게 띄우는지 | C53: C(주체)
...
